Workbook

Sheet DB_1,0
E5: SCOOT MASTER DATA BASE 1,0
B8: Prix "FMG"
A9: N° | B9: Moto | C9: Numero de serie | D9: Date d'arrivée | E9: Date départ | F9: Prix d'achat | G9: Prix de vente | H9: Etat | I9: Avance | J9: Reste | K9: REMARQUE | L9: Prix echange | M9: PRIX MOTO ECHANGE | N9: Benefice | O9: SEMAINE
A10: 1 | B10: PGO Tigra | C10: AIF-06472 | D10: 43937 | E10: 43939 | F10: 21000000 | G10: 23000000 | H10: VENDU | K10: Racing 150 fi orange | L10: 7000000 | M10: 16000000 | N10: =M10-(F10-L10) -> 2000000 | O10: Semaine 1
A11: =A10+1 -> 2 | B11: RACING 150 FI | C11: SR30BB-104952 | D11: 43938 | E11: 43938 | F11: 16000000 | G11: 16750000 | H11: VENDU | N11: =G11-F11 -> 750000 | O11: Semaine 1
A12: =A11+1 -> 3 | B12: RACING 150 FI | C12: SR30BB-214467 | D12: 43938 | E12: 43939 | F12: 16000000 | G12: 16750000 | H12: VENDU | N12: =G12-F12 -> 750000 | O12: Semaine 1
A13: =A12+1 -> 4 | B13: RACING 150 FI | C13: SR30BB-257336 | D13: 43938 | E13: 43941 | F13: 16000000 | G13: 16400000 | H13: VENDU | N13: =G13-F13 -> 400000 | O13: Semaine 2
A14: =A13+1 -> 5 | B14: RACING 150 FI ORANGE | C14: SR30BB-212575 | D14: 43939 | E14: 43941 | F14: 16000000 | G14: 16500000 | H14: VENDU | N14: =G14-F14 -> 500000 | O14: Semaine 2
A15: =A14+1 -> 6 | B15: RACING 150 FI | C15: SR30BB-211527 | D15: 43941 | E15: 43941 | F15: 14000000 | G15: 15500000 | H15: VENDU | N15: =G15-F15 -> 1500000 | O15: Semaine 1
A16: =A15+1 -> 7 | B16: RACING 150 FI | C16: SR30BB-221769 | D16: 43941 | E16: 43942 | F16: 14000000 | G16: 16000000 | H16: VENDU | N16: =G16-F16 -> 2000000 | O16: Semaine 2
A17: =A16+1 -> 8 | B17: RACING 150 FI | C17: SE30BB-101531 | D17: 43941 | E17: 43942 | F17: 14000000 | G17: 16000000 | H17: VENDU | N17: =G17-F17 -> 2000000 | O17: Semaine 2
A18: =A17+1 -> 9 | B18: RACING 125 FI | C18: SR25BA-100287 | D18: 43941 | E18: 43944 | F18: 14000000 | G18: 13250000 | H18: VENDU | N18: =G18-F18 -> -750000 | O18: Semaine 2
A19: =A18+1 -> 10 | B19: KYMCO MANY | C19: SE20BA-109586 | D19: 43941 | E19: 43948 | F19: 11000000 | G19: 12000000 | H19: VENDU | N19: =G19-F19 -> 1000000 | O19: Semaine 3
A20: =A19+1 -> 11 | B20: pgo TIGRA blanc | C20: AIF-00985 | D20: 43940 | E20: 43944 | F20: 20750000 | G20: 22500000 | H20: VENDU | N20: =G20-F20 -> 1750000 | O20: Semaine 2
A21: =A20+1 -> 12 | B21: KYMCO G5 MEGAFI noir | C21: SR25AC-101287 | D21: 43941 | E21: 43942 | F21: 15750000 | G21: 17250000 | H21: VENDU | N21: =G21-F21 -> 1500000 | O21: Semaine 2
A22: =A21+1 -> 13 | B22: KYMCO G5 /12 150 | C22: SE301000109 | D22: 43942 | E22: 43943 | F22: 13500000 | G22: 14600000 | H22: VENDU | N22: =G22-F22 -> 1100000 | O22: Semaine 2
... A45: =A44+1 -> 36 | B45: Kymco G5 MEGAFI | C45: SR25EA-118963 | D45: 43958 | E45: 43965 | F45: 15750000 | G45: 16500000 | H45: VENDU | N45: =G45-F45 -> 750000 | O45: Semaine 5
A46: =A45+1 -> 37 | B46: KYMCO G5 | C46: SE30AH-101313 | D46: 10/05/D2952020 | E46: 43963 | F46: 15250000 | G46: 16000000 | H46: VENDU | N46: =G46-F46 -> 750000 | O46: Semaine 5
A47: =A46+1 -> 38 | B47: KYMCO RACING 150 FI | C47: SR30BB-218936 | D47: 43962 | E47: 43962 | F47: 16250000 | G47: 18000000 | H47: VENDU | N47: =G47-F47 -> 1750000 | O47: Semaine 5
A48: =A47+1 -> 39 | B48: KYMCO RACING 150 FI | C48: SR30BB-267621 | D48: 43962 | E48: 43990 | F48: 16000000 | G48: 17000000 | H48: VENDU | N48: =G48-F48 -> 1000000 | O48: Semaine 8
A49: =A48+1 -> 40 | B49: KYMCO RACING 150 FI | C49: SR30BB-257671 | D49: 43962 | E49: 43962 | F49: 16250000 | G49: 17350000 | H49: VENDU | N49: =G49-F49 -> 1100000 | O49: Semaine 5
A50: =A49+1 -> 41 | B50: KYMCO RACING 150 FI | C50: SE30BB-104272 | D50: 43962 | E50: 43963 | F50: 16250000 | G50: 18000000 | H50: VENDU | N50: =G50-F50 -> 1750000 | O50: Semaine 5
A51: =A50+1 -> 42 | B51: KYMCO G5 MEGAFI | C51: SR30ED-100531 | D51: 43962 | E51: 43968 | F51: 22000000 | G51: 23000000 | H51: VENDU | N51: =G51-F51 -> 1000000 | O51: Semaine 6
A52: =A51+1 -> 43 | B52: KYMCO RACING 150 FI | C52: SR30BB-201638 | D52: 43962 | E52: 43962 | F52: 16250000 | G52: 17350000 | H52: VENDU | N52: =G52-F52 -> 1100000 | O52: Semaine 5
A53: =A52+1 -> 44 | B53: KYMCO G5 MEGAFI | C53: SR30ED-106165 | D53: 43962 | E53: 43962 | F53: 22000000 | G53: 22750000 | H53: VENDU | N53: =G53-F53 -> 750000 | O53: Semaine 5
A54: =A53+1 -> 45 | B54: KYMCO RACING 150 FI | C54: SR30BB-304728 | D54: 43962 | E54: 43962 | F54: 16250000 | G54: 18000000 | H54: VENDU | N54: =G54-F54 -> 1750000 | O54: Semaine 5
A55: =A54+1 -> 46 | B55: KYMCO RACING 150 FI | C55: SR30BB-104340 | D55: 43962 | E55: 43962 | F55: 16250000 | G55: 17350000 | H55: VENDU | N55: =G55-F55 -> 1100000 | O55: Semaine 5
A56: =A55+1 -> 47 | B56: KYMCO G5 MEGAFI | C56: SR30ED-112920 | D56: 43962 | E56: 43962 | F56: 22000000 | G56: 23000000 | H56: RESERVATION | I56: 20500000 | J56: =G56-I56 -> 2500000 | K56: Sera Occaz | N56: =G56-F56 -> 1000000 | O56: Semaine 5 | P56: ::
A57: =A56+1 -> 48 | B57: KYMCO G5 | C57: SE30AB-100689 | D57: 43962 | E57: 43967 | F57: 15250000 | G57: 16000000 | H57: VENDU | N57: =G57-F57 -> 750000 | O57: Semaine 6
A58: =A57+1 -> 49 | B58: KYMCO RACING 150 FI | C58: SR30BB-248665 | D58: 43962 | E58: 43962 | F58: 16250000 | G58: 18000000 | H58: VENDU | N58: =G58-F58 -> 1750000 | O58: Semaine 5
A59: =A58+1 -> 50 | B59: KYMCO RACING 150 FI | C59: SR30BB-257356 | D59: 43962 | E59: 43962 | F59: 16250000 | G59: 18500000 | H59: VENDU | N59: =G59-F59 -> 2250000 | O59: Semaine 5
A60: =A59+1 -> 51 | B60: KYMCO RACING 150 FI | C60: SR30BB-205443 | D60: 43963 | E60: 43964 | F60: 17000000 | G60: 18250000 | H60: VENDU | N60: =G60-F60 -> 1250000 | O60: Semaine 5
A61: =A60+1 -> 52 | B61: KYMCO RACING 150 FI | C61: SR30BB-246158 | D61: 43965 | E61: 43965 | F61: 16500000 | G61: 17500000 | H61: VENDU | N61: =G61-F61 -> 1000000 | O61: Semaine 5
A62: =A61+1 -> 53 | B62: KYMCO RACING 150 FI | C62: SR30BB-261740 | D62: 43965 | E62: 43965 | F62: 16250000 | G62: 17500000 | H62: VENDU | N62: =G62-F62 -> 1250000 | O62: Semaine 5
A63: =A62+1 -> 54 | B63: KYMCO RACING 150 FI | C63: SR30BB-225860 | D63: 43965 | E63: 43965 | F63: 16250000 | G63: 17500000 | H63: VENDU | N63: =G63-F63 -> 1250000 | O63: Semaine 5
A64: =A63+1 -> 55 | B64: KYMCO G5 | C64: SE25AA-142562 | D64: 43969 | E64: 43970 | F64: 10650000 | G64: 12250000 | H64: VENDU | N64: =G64-F64 -> 1600000 | O64: Semaine 6
A65: =A64+1 -> 56 | B65: KYMCO G5 | C65: SE25AA-145785 | D65: 43969 | E65: 43970 | F65: 10650000 | G65: 11250000 | H65: VENDU | N65: =G65-F65 -> 600000 | O65: Semaine 6
A66: =A65+1 -> 57 | B66: KYMCO G5 | C66: SE25AA-144469 | D66: 43969 | E66: 43969 | F66: 10650000 | G66: 11500000 | H66: VENDU | N66: =G66-F66 -> 850000 | O66: Semaine 6
A67: =A66+1 -> 58 | B67: KYMCO G5 | C67: SE25AA-106832 | D67: 43969 | E67: 44005 | F67: 10650000 | G67: 9000000 | H67: VENDU | N67: =G67-F67 -> -1650000 | O67: Semaine 11
A68: =A67+1 -> 59 | B68: KYMCO G5 | C68: SE25AA-103273 | D68: 43969 | E68: 43973 | F68: 10650000 | G68: 11250000 | H68: VENDU | N68: =G68-F68 -> 600000 | O68: Semaine 6
...

Sheet DB_ClientSM
I2: LISTE CLIENTs SCOOT MASTER
A4: Numéros | C4: Numéro facture/BL
A5: N° Moto | B5: N° Moteur | C5: N° Facture | D5: N°B.L | E5: Marque moto | F5: Nom | G5: Prenom | H5: N° CIN | I5: Adresse | J5: Telephone | K5: Type | L5: Date de l'achat | M5: Montant en Ar
B6: 4NF032020(N° Cadre: SA165-930209) | C6: 107 | E6: YAMAHA ZR Evolution | F6: RAZAFINDRAKOTO | G6: Harimanana Fabien Emma | H6: 101252079754 | I6: Lot II A 17 Amboditsiry | J6: /0342781514 | L6: 43895 | M6: 2000000
A7: 1 | B7: AIF-06472 | C7: 1 | D7: - | E7: PGO Tigra | F7: RAHAJANIRAINY | G7: Taratra | H7: 515011020120 | I7: Lot 65 Bis Ambohibao | J7: /0340013065 | L7: 43939 | M7: =23000000/5 -> 4600000
A8: 2 | B8: SR30BB-104952 | C8: 2 | D8: - | E8: Kymco Racing fi | F8: RAKOTOARISOA | G8: Liva | H8: 102031021943 | I8: Lot A II 6 Ter Mandrosoa | L8: 43939 | M8: =16750000/5 -> 3350000
A9: 3 | B9: SR30BB-214467 | C9: 3 | E9: Kymco Racing fi | F9: RANARISON | G9: Tokiniaina Fanomezantsoa | H9: 117051017412 | I9: Lot I A H 110 B Avaratsena Itaosy | J9: /0346111251 | L9: 43939 | M9: =16750000/5 -> 3350000
A10: 6 | B10: SR30BB-211527 | C10: 6 | E10: Kymco Racing fi | F10: RAKOTOARINIVO | G10: Manitra Fitiavana | H10: 101231161689 | I10: Lot IVP 206 Ankadifotsy | J10: /0337036054 | L10: 43942 | M10: =15500000/5 -> 3100000
A11: 5 | B11: SR30BB-212575 | C11: - | D11: 1 | E11: RACING 150 FI ORANGE | F11: RAKOTOMALALA | G11: Solofomandimby | H11: 102091451210 | I11: Lot III X 117 Bis Anosibe | L11: 43941 | M11: =16500000/5 -> 3300000
A12: 7 | B12: SR30BB-221769 | C12: 5 | E12: Kymco Racing fi | F12: RAFALIMANANA | G12: Lanto Nambinintsosa | H12: 101251183655 | I12: Lot II 35 DGA Bis Ankadindramamy | J12: /0344148620 | L12: 43942 | M12: 3200000
A13: 8 | B13: SE30BB-101531 | C13: 7 | E13: Kymco Racing fi | F13: RAZAFINDRIANONY | G13: Jos Isèdore Fidèle | H13: 517011008282 | I13: II M 71 AB Androhibe | L13: 43942 | M13: 3200000
A14: 12 | B14: SR25AC-101287 | C14: 8 | E14: kymco G5 megafi | F14: RASOLONJATO | G14: Anditiana Julio | H14: 101221087239 | I14: Lot VM 53 C Androndrakely | J14: /0341701151 | L14: 43942 | M14: =17250000/5 -> 3450000
A15: 14 | B15: SE301000131 | D15: 10 | E15: KYMCO G5 /12 150 | F15: RAZAFINDRAKOTO | G15: Rivoniaina Eli | H15: 101251181708 | I15: II H 26 FH Bis Nanisana | J15: /0337386317 | L15: 43943 | M15: =14400000/5 -> 2880000
A16: 13 | B16: SE301000109 | C16: 47 | E16: KYMCO G5 /12 150 | F16: RAKOTONIAINA | G16: Julien | H16: 101124107588 | I16: Lot III T I9 Bis Mandrangobato | J16: /0346057249 | K16: Acheteur extérieur: vendu par RAKOTININDRINA Elysée | L16: 43943 | M16: =14600000/5 -> 2920000
A17: 13 | B17: SE301000109 | C17: 11 | E17: KYMCO G5 /12 150 | F17: RAKOTONINDRINA | G17: Elysée | H17: 110051004731 | I17: IPA 290 Itaosy | J17: /0332185447/0346052185 | L17: 43943 | M17: =14600000/5 -> 2920000
A18: 11 | B18: AIF-00985 | C18: 12 | E18: pgo TIGRA blanc | F18: RAKOTONANAHARY | G18: Tolotriniaina | H18: 102071005234 | I18: II J 91 FMN Ivandry | J18: /0344371401 | L18: 43944 | M18: =22500000/5 -> 4500000
A19: 9 | B19: SR25BA-100287 | C19: 13 | E19: RACING 125 FI | F19: RAOELISON | G19: Mahery Tina | H19: 117171015253 | I19: Lot IAV 312 C Iavoloha | J19: /0341090783 | L19: 43944 | M19: =13250000/5 -> 2650000
B20: SD244C-302515 | C20: 14 | E20: Kymco GP | F20: RAKOTOARISON | G20: Andry Mihaja | H20: 101231161981 | I20: Lot IVP 120 Ankadifotsy | J20: /0345704276 | L20: 43944 | M20: 1950000
A21: 18 | B21: SE251000102 | C21: 15 | D21: 15 | E21: KYMCO G5 /10 125 | F21: ANDRIAMITANTSOSA | G21: Miora Patrick | H21: 117171012337 | I21: Lot II B 84 Mahalavolona | J21: /0341452866 | L21: 43944 | M21: =11000000/5 -> 2200000
A22: 15 | B22: SE251100303 | C22: 15.5 | D22: 16 | E22: KYMCO G5 /12 125 | F22: RANDRIANARIVELO | G22: Faly Luca | H22: 101241130876 | I22: Lot III 025 C Mananjara | J22: /0343757829 | L22: 43944 | M22: =13425000/5 -> 2685000
A23: 4 | B23: SR30BB-257336 | C23: - | D23: 2 | E23: RACING 150 FI | F23: RAZAFITSALAMA | G23: Nomentsoa Toavina | H23: 101242158316 | I23: Lot IV Y 56 JM Ter Anosipatrana | J23: /0345813833 | L23: 43946 | M23: =16400000/5 -> 3280000
A24: 17 | B24: E3B8E9388 | C24: 16 | D24: - | E24: C2 Type 2 | F24: RAHAJANIRAINY | G24: Taratra | H24: 515011020120 | I24: Lot 65 Bis Ambohibao | J24: /0340013065 | L24: 43947 | M24: =16650000/5 -> 3330000
A25: 10 | B25: SE20BA-109586 | C25: 17 | D25: - | E25: KYMCO MANY | F25: ANDRIAMANANTENA | G25: Fifaliana | H25: 101251143350 | I25: II B 170 Bis K Manjakaray | J25: /0343161321 | L25: 43948 | M25: =12000000/5 -> 2400000
A26: 16 | B26: SE251101098 | C26: 18 | D26: - | E26: KYMCO G5 /12 125 | F26: RAKOTOVAO | G26: Nirina José | H26: 101251183598 | I26: II E 47 G Ampanotokana | J26: /0345225792 | L26: 43948 | M26: =13225000/5 -> 2645000
A27: 15 | B27: SE251100303 | C27: 19 | D27: - | E27: KYMCO G5 /12 125 | F27: RAHARISEHENO | G27: Fenosoa | H27: 101222052041 | I27: Lot IPK A 01 Ambanilalana | J27: /0330159562 | L27: 43948 | M27: ='DB_1,0'!G24/5 -> 2685000
A28: 19 | B28: SR30ED-118212 | C28: 20 | D28: - | E28: KYMCO G5 MEGAFI gris | F28: RANDRIANARISON | G28: Andre | H28: 113091010913 | I28: K7 333 Mamory Ivato | J28: /0341687027 | L28: 43949 | M28: =24000000/5 -> 4800000
A29: 21 | B29: SD25-5501097 | C29: 21 | D29: - | E29: KYMCO GP | F29: RAZAFARISON | G29: Tiana Mickäel | H29: 117011019250 | I29: AZ 31 AI Antokotanitsara | J29: /0342137177 | L29: 43949 | M29: =10500000/5 -> 2100000
A30: 24 | B30: SD25-5500578 | C30: 22 | D30: - | E30: KYMCO GP | F30: RAZAFARISON | G30: Tiana Mickäel | H30: 117011019250 | I30: AZ 31 AI Antokotanitsara | J30: /0342137177 | L30: 43949 | M30: =10250000/5 -> 2050000
A31: 20 | B31: SR30BB-204936 | C31: 23 | D31: - | E31: RACING 150 FI | F31: RAKOTONANAHARY | G31: Andry | H31: 102071012740 | I31: Lot C 57 A Bis Ambohimanarina | J31: /0341360761 | L31: 43949 | M31: =17250000/5 -> 3450000
B32: 4UF-101-388 | C32: 110 | D32: - | E32: YAMAHA Jog Pro | F32: RAMBELOSON | G32: Mampianimanana Altess | H32: 108091014368 | I32: Lot 44 Bis Itaosy | J32: /0342770363 | L32: 43949 | M32: 1100000
A33: 23 | B33: SD25-5500679 | C33: 29 | D33: - | E33: KYMCO GP | F33: RAMIANDRISOA | G33: Mioraniaina | H33: 208012007764 | I33: Avaratsena Ambohimasoa | J33: /0349291116 | L33: 43953 | M33: =10550000/5 -> 2110000
A34: 22 | B34: SD25-5501266 | C34: 30 | D34: - | E34: KYMCO GP | F34: RASOAMANAHIRANA | G34: Marie Louisette | H34: 117012035400 | I34: AZ QZ KI/D Antandrokomby | J34: /0346603090 | L34: 43953 | M34: =10250000/5 -> 2050000
A35: 25 | B35: SR25AA-200597 | D35: 12 | E35: KYMCO G5 /10 125 | F35: RAKOTONINDRINA | G35: Elysée | H35: 110051004731 | I35: IPA 290 Itaosy | J35: /0332185447/0346052185 | L35: 43955 | M35: =14000000/5 -> 2800000
A36: 27 | B36: SJ25EC-105365 | D36: 11 | E36: KYMCO GP FI | F36: RAKOTOARISON | G36: Tiriac Rivoaritrema | H36: 101231134142 | I36: Lot IV3 103 Andravoahangy | J36: /0342944143 | L36: 43955 | M36: =11350000/5 -> 2270000
A37: 26 | B37: SJ25KA-115857 | C37: 32 | D37: - | E37: KYMCO GP FI | F37: ANDRIANTAHINANAHARY | G37: Roland le Glorieux | H37: 515011018783 | I37: Lot AZ 24T Anosizato | J37: /0346028301 | L37: 43955 | M37: 2400000
A38: 31 | B38: SD25UA-120812 | C38: 36 | D38: - | E38: KYMCO GP Carb | F38: ANDRIAMOSA | G38: Mamy Ny Aina | H38: 102031026052 | I38: Lot II AB 35 Andrononobe | J38: /0348332300 | L38: 43956 | M38: 2000000
A39: 30 | B39: SD25UA-227460 | C39: - | D39: 13 | E39: KYMCO GP Carb | F39: RAKOTOMALALA | G39: Tinaharivelo Ainavatosoa | H39: 103071010800 | I39: Mahazoarivo | J39: /0346035817 | L39: 43956 | M39: =9950000/5 -> 1990000
A40: 35 | B40: SE25AA-115993 | C40: 37 | D40: - | E40: KYMCO G5 | F40: RANDRIAFENOMANANA | G40: Herison Olivier | H40: 101251100686 | I40: III A 38 Andafiatsimo Tanjombato | L40: 43958 | M40: =13500000/5 -> 2700000
A41: 28 | B41: SD25UA-200597 | C41: 34 | D41: - | E41: KYMCO GP Carb | F41: ANDRIAMANANTENA | G41: Toky | H41: 102011016397 | I41: Lot B I 40 Ter amboaroy | J41: /0348119049 | L41: 43956 | M41: =9400000/5 -> 1880000
A42: 47 | B42: SR30ED-112920 | E42: KYMCO G5 MEGAFI | F42: SERA OCCAZ | J42: /0345813833 | L42: 43962 | M42: =22000000/5 -> 4400000
...

Sheet Double_C
B2: Désignation | C2: Date | D2: Débit | E2: Crédit | H2: invest départ : 9 900 000
B3: Investissement | C3: 45114 | E3: 2900000
A4: 1 | B4: Achat G5 125 FI /12 | C4: 45114 | D4: 2100000
B5: Vente G5 125 FI /12 | C5: 45121 | E5: 2500000
A6: 2 | B6: Achat G5 Megafi | C6: 45132 | D6: 3300000 | H6: 02/09/2023 : - 3 000 000
B7: Investissement | C7: 45131 | E7: 7000000
A8: 3 | B8: Achat VJR 110 | C8: 45138 | D8: 2050000
A9: 4 | B9: Achat G5 125 carbu | C9: 45138 | D9: 2050000
A10: 5 | B10: Achat G5 125 FI | C10: 45138 | D10: 2100000
B11: Dépenses autres | C11: 45138 | D11: 120000
B12: Vente G5 125 carbu | C12: 45138 | E12: 2300000
A13: 6 | B13: Achat G5 125 FI | C13: 45156 | D13: 2120000
B14: Vente VJR 110 | C14: 45160 | E14: 2250000
B15: Retrait Johann | C15: 45171 | D15: 3000000
B16: Vente G5 125 FI | C16: 45171 | E16: 2400000
B17: Vente G5 Megafi | C17: 45173 | E17: 3600000
B18: Vente G5 125 FI | C18: 45178 | E18: 2400000
A19: 7 | B19: Achat G5 125 carbu | C19: 45188 | D19: 1900000
A20: 8 | B20: Achat G5 125 carbu | C20: 45188 | D20: 1900000
A21: 9 | B21: Achat G5 125 FI | C21: 45188 | D21: 2150000
A22: 10 | B22: Achat G5 150 carbu | C22: 45188 | D22: 2400000
B23: Vente G5 125 carbu | C23: 45188 | E23: 2100000
B24: Dépenses autres | C24: 45188 | D24: 30000
B25: Vente G5 125 carbu | C25: 45204 | E25: 2200000
A26: 11 | B26: Achat G5 125 FI | C26: 45211 | D26: 2100000
B27: Transport - lavage - méca TW | C27: 45215 | D27: 30000
B34: TOTAL | D34: =D4+D6+D8+D9+D10+D11+D13+D15+D19+D20+D21+D22+D24+D27+D26 -> 27350000 | E34: =E3+E5+E7+E12+E14+E16+E17+E18+E23+E25 -> 29650000
B35: RESTE | E35: =E34-D34 -> 2300000
A45: N° | B45: Désignation | C45: Date d'arrivée | D45: Date de départ | E45: Prix d'achat | F45: Prix de vente | G45: Bénéfice
A46: 1 | B46: G5 125 FI /12 | C46: 45114 | D46: 45121 | E46: 2100000 | F46: 2500000 | G46: =F46-E46 -> 400000
A47: 2 | B47: G5 Megafi 150 | C47: 45132 | D47: 45173 | E47: 3300000 | F47: 3600000 | G47: =F47-E47 -> 300000
A48: 3 | B48: VJR 110 | C48: 45138 | D48: 45160 | E48: 2090000 | F48: 2250000 | G48: =F48-E48 -> 160000
A49: 4 | B49: G5 125 carbu | C49: 45138 | D49: 45138 | E49: 2090000 | F49: 2300000 | G49: =F49-E49 -> 210000
A50: 5 | B50: G5 125 FI | C50: 45138 | D50: 45178 | E50: 2140000 | F50: 2400000 | G50: =F50-E50 -> 260000
A51: 6 | B51: G5 125 FI | C51: 45156 | D51: 45171 | E51: 2120000 | F51: 2400000 | G51: =F51-E51 -> 280000
A52: 7 | B52: G5 125 carbu | C52: 45188 | D52: 45188 | E52: 1915000 | F52: 2100000 | G52: =F52-E52 -> 185000
A53: 8 | B53: G5 125 carbu | C53: 45188 | D53: 45204 | E53: 1915000 | F53: 2200000 | G53: =F53-E53 -> 285000
A54: 9 | B54: G5 125 FI | C54: 45188 | E54: 2150000
A55: 10 | B55: G5 150 carbu | C55: 45188 | E55: 2400000
A56: 11 | B56: G5 125 FI | C56: 45211 | E56: 2130000
...

Sheet prix pieces refa hanao achat
A2: roulement 6202 | C2: 20000
A3: roulement 6204 | C3: 20000
A4: Chaine | C4: 40000
A5: CDI | C5: 275000
A6: pompe | C6: 125000
A7: Tendeur | C7: 50000

Sheet DB_Pièces_SM
A4: Désignation | B4: Référence | C4: Quantité | D4: Prix unitaire(fmg)
A5: Courroie | B5: LGR7 | C5: 2 | D5: 600000
A6: Cache echap | B6: Cygnus | C6: 2 | D6: 450000
A7: Cache echap | B7: Racing | C7: 3 | D7: 450000
A8: Cache echap | B8: G5 | C8: 1 | D8: 400000
A9: Cache echap | B9: Racing King | C9: 1 | D9: 600000
A10: Embrayage | B10: Kit | C10: 1 | D10: 1200000
A11: Embrayage | B11: simple | C11: 7 | D11: 650000
A12: Poignets kitako | C12: 5 | D12: 75000
A13: Batterie | B13: ABM 7A | C13: 9 | D13: 275000

Sheet Liste prospects
D2: LISTE PROSPECTs SCOOT MASTER
A5: Nom | B5: Prenom | C5: Téléphone | D5: Commande
B6: Alain | C6: /0342052272 | D6: G5
A7: RAZAFINDRAKOTO | B7: Rivoniaina Eli | C7: /0337386317 | D7: Racing
A8: RAKOTONINDRINA | B8: Elysée | C8: /0346052185 | D8: Racing et G5
A9: Moum | B9: Serasera | C9: /0340124068 | D9: Racing et G5
A10: Mr | B10: Patrick | C10: /0338374631 | D10: Racing | E10: a appeler demain
A11: Mr | B11: Fidy | C11: /0346889613 | D11: 10 Racing arrivage(15 M)
A12: Mr | B12: Tantely | C12: /0345208869/0345117622 | D12: Racing KCC 150 | E12: a appeler demain
A13: Mr | B13: Valimbavaka | C13: /034 29 987 19 | D13: GP
A14: Mr | B14: Ando | C14: /0341420019 | D14: G5 125cc carbu par 12
A15: Mr | B15: Dylan | C15: /0320545950 | D15: G5 150 ou racing 150 carbu
A16: Mr | B16: Tojo | C16: /0345610957 | D16: Racing 150 | E16: *A appeler avant arrivage
A17: Mr | B17: Tax | C17: /0343365595 | D17: G5 | E17: *A appeler avant arrivage
A18: Mr | B18: Patron be | C18: /0324457915 | D18: G6 | E18: *A appeler avant arrivage
A19: Mr | B19: José | C19: /0340233207 | D19: G5 150 | E19: *A appeler avant arrivage
A20: Mr | B20: Mika | C20: /0340326191 | D20: G5 | E20: *A appeler avant arrivage
A21: Mahavoky | B21: Feno | C21: /0337305083 | D21: G5 | E21: *A appeler avant arrivage
A22: Mr et Fils | B22: Fidy | C22: /0341849356 | D22: G5 150 /12 | E22: *A appeler avant arrivage
A23: Cousin Andry | B23: Antsa | C23: /0341593254 - /0330680694 | D23: G5 150 /12 FI
B24: mika | C24: /0347473560
B25: CLT | C25: /0344071556 | D25: G5 125 fi (02/07/2020)
B26: Mr Rajo | C26: /0342060711 | D26: Racing | E26: *A appeler avant arrivage

Sheet DB
C2: DATA BASE "MOTOS" - SCOOT MASTER -
A6: Date d'achat | B6: N° | C6: Marque | D6: Numéro de série | E6: Puissance | F6: PRIX d'achat | G6: Avance reservation | H6: Reste avance | I6: Prix de vente | J6: Etat | K6: Date de vente | L6: Bénéfice | M6: Livraison
A7: 43939 | B7: 1 | C7: PGO Tigra FI | D7: A1F00985 | E7: 100 cc | F7: 20750000 | I7: 22500000 | J7: VENDU | K7: 43944 | L7: =I7-F7 -> 1750000 | M7: OK
A8: 43941 | B8: =B7+1 -> 2 | C8: KYMCO MANY FI | D8: SE20BA-109586 | E8: =E7 -> 100 cc | F8: 11000000 | I8: 12000000 | J8: VENDU | K8: 43948 | L8: =I8-F8 -> 1000000 | M8: OK
A9: 43940 | B9: =B8+1 -> 3 | C9: KYMCO G5 MEGAFI /12 | D9: SR25AC-101287 | E9: =E8 -> 100 cc | F9: 15750000 | I9: 17250000 | J9: VENDU | K9: 43942 | L9: =I9-F9 -> 1500000 | M9: OK
A10: 43940 | B10: =B9+1 -> 4 | C10: KYMCO RACING FI | D10: SR30BB-212575 | E10: =E9 -> 100 cc | F10: 16000000 | I10: 16500000 | J10: =J9 -> VENDU | K10: 43941 | L10: =I10-F10 -> 500000 | M10: OK
A11: 43941 | B11: =B10+1 -> 5 | C11: KYMCO RACING FI | D11: SE30BB-101531 | E11: =E10 -> 100 cc | F11: 14000000 | I11: 16000000 | J11: VENDU | K11: 43942 | L11: =I11-F11 -> 2000000 | M11: OK
A12: 43941 | B12: =B11+1 -> 6 | C12: KYMCO RACING FI | D12: SR30BB-221769 | E12: =E11 -> 100 cc | F12: 14000000 | I12: 16000000 | J12: VENDU | K12: 43941 | L12: =I12-F12 -> 2000000 | M12: OK
A13: 43938 | B13: =B12+1 -> 7 | C13: KYMCO RACING FI | D13: SR30BB-257336 | E13: =E12 -> 100 cc | F13: 16000000 | I13: 16400000 | J13: VENDU | K13: 43941 | L13: =I13-F13 -> 400000 | M13: OK
A14: 43941 | B14: =B13+1 -> 8 | C14: KYMCO RACING FI | D14: SR25BA-100287 | E14: =E13 -> 100 cc | F14: 14000000 | I14: 13000000 | J14: VENDU | K14: 43944 | L14: =I14-F14 -> -1000000 | M14: OK | N14: Cache bat commande
A15: 43941 | B15: =B14+1 -> 9 | C15: KYMCO RACING FI | D15: SR30BB-211527 | E15: =E14 -> 100 cc | F15: 14000000 | I15: 15500000 | J15: VENDU | K15: 43942 | L15: =I15-F15 -> 1500000 | M15: OK
A16: 43942 | B16: =B15+1 -> 10 | C16: KYMCO G5 | D16: SE301000109 | E16: =E15 -> 100 cc | F16: 13500000 | I16: 14600000 | J16: VENDU | K16: 43943 | L16: =I16-F16 -> 1100000 | M16: OK
A17: 43942 | B17: =B16+1 -> 11 | C17: =C16 -> KYMCO G5 | D17: SE301000131 | E17: =E16 -> 100 cc | F17: =F16 -> 13500000 | I17: 14400000 | J17: VENDU | K17: 43943 | L17: =I17-F17 -> 900000 | M17: OK
A18: 43942 | B18: =B17+1 -> 12 | C18: =C17 -> KYMCO G5 | D18: SE251101098 | E18: =E17 -> 100 cc | F18: 12650000 | I18: 13225000 | J18: VENDU | K18: 43948 | L18: =I18-F18 -> 575000 | M18: OK
A19: 43942 | B19: =B18+1 -> 13 | C19: =C18 -> KYMCO G5 | D19: SE251100303 | E19: =E18 -> 100 cc | F19: =F18 -> 12650000 | I19: 13425000 | J19: VENDU | K19: 43944 | L19: =I19-F19 -> 775000 | M19: OK
A20: 43942 | B20: =B19+1 -> 14 | C20: YAMAHA C2 Type 2 | D20: E3B8E9388 | E20: =E19 -> 100 cc | F20: 14950000 | I20: 17000000 | J20: VENDU | K20: 43947 | L20: =I20-F20 -> 2050000 | M20: OK
A21: 43943 | B21: =B20+1 -> 15 | C21: KYMCO G5 /10 | D21: SE251000102 | E21: 100 cc | F21: 10000000 | I21: 11000000 | J21: VENDU | K21: 43944 | L21: =I21-F21 -> 1000000 | M21: OK
A22: 43945 | B22: =B21+1 -> 16 | C22: KYMCO G5 MEGAFI /12 | D22: SR30ED-118212 | E22: 100 cc | F22: 21600000 | I22: 24000000 | J22: VENDU | K22: 43949 | L22: =I22-F22 -> 2400000 | M22: OK
A23: 43945 | B23: =B22+1 -> 17 | C23: KYMCO RACING FI | D23: SR30BB-204936 | E23: 100 cc | F23: 15000000 | I23: 17250000 | J23: VENDU | K23: 43949 | L23: =I23-F23 -> 2250000 | M23: OK
F33: Total Moto I.V t@1° | G33: =F7+F8+F9+F10+F11+F12+F13+F14+F15 -> 135500000

Sheet Liste ventes motos
B2: LISTE VENTES MOTOS S02 et S03
G4: Prix "FMG"
A5: Num vente | B5: Numéro Moto | C5: Marque | D5: Numéro de serie | E5: Prix de vente | F5: Date
A6: 1 | B6: 4 | C6: KYMCO RACING FI | D6: SR30BB-212575 | E6: 16500000 | F6: 43941
A7: =A6+1 -> 2 | B7: 7 | C7: KYMCO RACING FI | D7: SR30BB-221769 | E7: 16000000 | F7: =F6 -> 43941
A8: =A7+1 -> 3 | B8: 8 | C8: KYMCO RACING FI | D8: SR30BB-257336 | E8: 16400000 | F8: =F7 -> 43941
A9: =A8+1 -> 4 | B9: 10 | C9: KYMCO RACING FI | D9: SR30BB-211527 | E9: 15500000 | F9: 43942
A10: =A9+1 -> 5 | B10: 5 | C10: KYMCO RACING FI | D10: SE30BB-101531 | E10: 15000000 | F10: 43942
A11: =A10+1 -> 6 | B11: 3 | C11: KYMCO G5 MEGAFI /12 | D11: SR25AC-101287 | E11: 17250000 | F11: 43942
A12: =A11+1 -> 7 | B12: 12 | C12: KYMCO G5 | D12: SE301000131 | E12: 14400000 | F12: 43943
A13: =A12+1 -> 8 | B13: 11 | C13: KYMCO G5 | D13: SE301000109 | E13: 14600000 | F13: 43943
A14: =A13+1 -> 9 | B14: 1 | C14: PGO Tigra FI | D14: A1F00985 | E14: 22500000 | F14: 43944
A15: =A14+1 -> 10 | B15: 9 | C15: KYMCO RACING FI | D15: SR25BA-100287 | E15: 14000000 | F15: 43944
A16: =A15+1 -> 11 | B16: 16 | C16: KYMCO G5 /10 | D16: SE251000102 | E16: 11000000 | F16: 43944
A17: =A16+1 -> 12 | B17: 14 | C17: KYMCO G5 | D17: SE251100303 | E17: 13425000 | F17: 43944
A18: =A17+1 -> 13 | B18: 17 | C18: C2 Type 2 | D18: E3B8E9388 | E18: 16650000 | F18: 43947
A19: =A18+1 -> 14 | B19: 10 | C19: KYMCO MANY | D19: SE20BA-109586 | E19: 12000000 | F19: 43948
A20: =A19+1 -> 15 | B20: 16 | C20: KYMCO G5 /12 125 | D20: SE251101098 | E20: 13225000 | F20: 43948
... A24: =A23+1 -> 19 | B24: 24 | C24: KYMCO GP | D24: SD25-5500578 | E24: 10250000 | F24: 43949
D27: Chiffre d'affaire => | E27: =SUM(E6:E24) -> 290450000

Sheet liste achats
B2: LISTE DES ACHATS : "MOTOS"
D5: Prix FMG
A6: Numéro achat | B6: Date d'achat | C6: Prix
A7: 1 | B7: 43937 | C7: 21000000
A8: 2 | B8: 43938 | C8: 48000000
A9: 3 | B9: 43940 | C9: 20750000
A10: 4 | B10: 43941 | C10: 67000000
A11: 5 | B11: 43941 | C11: 15750000
A12: 6 | B12: 43942 | C12: 67250000
A13: 7 | B13: 43943 | C13: 10000000
A14: 8 | B14: 43945 | C14: 36600000 | E14: =45000000+20000000+150000000+15250000 -> 230250000
A15: 9 | B15: 43948 | C15: 36000000
A16: 10 | B16: 43950 | C16: 43200000
A17: =A16+1 -> 11 | B17: 43953 | C17: 2000000 | D17: avance
A18: =A17+1 -> 12 | B18: 43954 | C18: 26500000
A19: =A18+1 -> 13 | B19: 43956 | C19: 63650000
A20: =A19+1 -> 14 | B20: 43958 | C20: 40000000
A21: =A20+1 -> 15 | B21: 43959 | C21: 20000000
A22: =A21+1 -> 16 | B22: 43961 | C22: 45000000

Sheet Ventes pieces
A2: PIECES
A4: Désignation | B4: Nombre vendu | C4: Prix unitaire | D4: Total | E4: Nombre en stock
A5: Poignet Kitako | B5: =9-E5 -> 0 | C5: =90000 -> 90000 | D5: =C5*B5 -> 0 | E5: =9 -> 9
A6: Batterie | B6: 5 | C6: =250000 -> 250000 | D6: =B6*C6 -> 1250000 | E6: =13 -> 13

Sheet Capital Dada sy Neny
F2: =E2*11 -> 0
A15: TOTAL GENERAL | B15: =SUM(B7:B9) -> 0 | C15: =SUM(C7:C9) -> 0 | D15: =SUM(D7:D9) -> 0 | E15: =SUM(E7:E9) -> 0 | F15: =SUM(F7:F9) -> 0
A27: Investissement de base : | B27: 136 000 000 Fmg
A28: Second Investisement : | B28: 150 000 000 Fmg
A29: TOTAL : | B29: 286 000 000 Fmg

Sheet Dépenses_Se04
A2: Liste dépenses S04
D4: PRIX "fmg"
A5: Désignation | B5: Date | C5: Prix
A6: Arbre a cam | B6: 43955 | C6: 100000
A7: Mecanicien | B7: 43955 | C7: 75000
A8: essence reparation | B8: 43956 | C8: 50000
A9: Arbre a cam | B9: 43956 | C9: 100000
A10: essence | B10: 43957 | C10: 50000
A11: cable accelerateur + essence GP | B11: 43957 | C11: 225000
A12: Mecanicien | B12: 43957 | C12: 275000
A13: livrasion Faniry | B13: 43958 | C13: 65000
A14: Mecanicien | B14: 43958 | C14: 150000
A15: Gasoil | B15: 43960 | C15: 50000
A16: Kevin-Steph Andravoahangy | B16: 43961 | C16: =560000 -> 560000 | D16: Chaines 250 000 | E16: Cadenas 47500 | F16: attache :10000 | G16: fil:60000 | H16: Papier collant: 15000 | I16: Gel sy impec : 62500
I17: yaourt sy coca : 10000
B30: TOTAL | C30: =SUM(C6:C27) -> 1700000

Sheet Dépenses_Se03
A2: Liste dépenses S03
D4: PRIX "fmg"
A5: Désignation | B5: Date | C5: Prix
A6: Fasika et gravillon (station de lavage) | B6: 43948 | C6: 50000
A7: Essence | B7: 43948 | C7: 100000
A8: Mécanicien (04 GP) | B8: 43948 | C8: 400000
A9: Essence | B9: 43950 | C9: 50000
A10: Kevin (diluant, degripant, fil,essence…) | B10: 43951 | C10: 200000
A11: Huile moteur | B11: 43951 | C11: 200000
A12: Bobine | B12: 43951 | C12: 500000
A13: Clé douille | B13: 43951 | C13: 180000
A14: Fer à souder | B14: 43951 | C14: 65000
A15: Tamis | B15: 43951 | C15: 100000
A16: Chaînes | B16: 43951 | C16: 100000
A17: Roulement + Presse arbre a cam | B17: 43951 | C17: 100000
... A25: Petrole | B25: 43952 | C25: 25000
B28: TOTAL | C28: =SUM(C6:C25) -> 3000000

Sheet Détails Sortie S02
C3: DETAIL SORTIE S02
F6: PRIX en FMG
B7: Date | C7: Désignation | D7: Prix
B8: 43942 | C8: Achat motos (G5 : 04, Cygnus : 01) | D8: 67250000
B9: 43942 | C9: Impression Facture | D9: 50000
B10: 43943 | C10: Achat moto G5 / 10 | D10: 10000000
B11: 43943 | C11: Vazah mecanicien | D11: 50000
B12: 43945 | C12: Achat G5 Megafi 150 | D12: 21600000
B13: 43945 | C13: Achat RACING FI 150 | D13: 15000000
B14: 43945 | C14: Impression, Essence, Charge batterie | D14: 125000
B15: 43945 | C15: Clé G5 | D15: 75000
B16: 43945 | C16: Aina mecanicien (02 motos) | D16: 125000
B17: 43946 | C17: Toerana fanaovana lavage et toutes sujétions | D17: =250000+150000+25000 -> 425000
B18: 43946 | C18: Mecanicien C2 et Racing | D18: 325000
C28: TOTAL | D28: =D16+D15+D14+D13+D12+D11+D10+D9+D8+D17+D18 -> 115025000

Sheet Flux S04
D2: Flux Entrée et Sortie CAISSE MASTER SCOOT - S04
A4: PRIX "FMG"
B5: Entrée | C5: Sortie | D5: Date | E5: Désignation
B6: 69800000 | D6: 43953 | E6: Caisse fin S03 | G6: Bénéfice S04 : | H6: =8650000 -> 8650000
B7: 10550000 | D7: 43953 | E7: Prix GP
B8: 10250000 | D8: 43953 | E8: Prix GP
C9: 26500000 | D9: 43954 | E9: Achat motos Rajou
B11: 200000 | D11: 43955 | E11: Benef av @ Retro (couvre depense)
C12: 100000 | D12: 43955 | E12: Arbre a cam gp
B13: 11350000 | D13: 43955 | E13: Prix GP n°27
B14: 14000000 | D14: 43955 | E14: Prix G5 N°25
B15: 12000000 | D15: 43955 | E15: Prix GP n°26
C16: 75000 | D16: 43955 | E16: Mecanicien
C17: 80000000 | D17: 43956 | E17: Achat motos Rajou
C18: 100000 | D18: 43956 | E18: Arbre a cam gp
B19: 18350000 | D19: 43956 | E19: Reste achat motos
B20: 8000000 | D20: 43956 | E20: Prix GP n°29
B21: 9950000 | D21: 43956 | E21: Prix GP n°30
B22: 10000000 | D22: 43956 | E22: Prix GP n°31
C23: 600000 | D23: 43957 | E23: essences, cable, mecano
C24: 40000000 | D24: 43958 | E24: Achat motos Rajou
C25: 65000 | D25: 43958 | E25: Livraison Faniry
B26: 13500000 | D26: 43958 | E26: Prix G5 N°35
B27: 24250000 | D27: 43958 | E27: Reste achat motos
C28: 4250000 | D28: 43958 | E28: Avance motos
C29: 150000 | D29: 43958 | E29: Mecanicien
B30: 4250000 | D30: 43959 | E30: Avance motos
C31: 20000000 | D31: 43959 | E31: Avance motos ihany
C32: 50000 | D32: 43960 | E32: Gazoil
B33: 16000000 | D33: 43960 | E33: Avance Sera Occas pour arrivage
C34: 560000 | D34: 43961 | E34: Kevin-Steph Andravoahangy
C35: 45000000 | D35: 43961 | E35: Achat motos Rajou
A36: TOTAL | B36: =SUM(B6:B8,B11,B13:B15,B19:B22,B26:B27,B30,B33) -> 232450000 | C36: =SUM(C9:C10,C12,C16:C18,C23:C25,C28:C29,C31:C32,C34:C35) -> 217450000 | D36: RESTE: | E36: =B36-C36 -> 15000000 | F36: =E36-H6 -> 6350000 | G36: <= RESTE - Benefice

Sheet FLux S03
D2: Flux Entrée et Sortie CAISSE MASTER SCOOT - S03
A4: PRIX "FMG"
B5: Entrée | C5: Sortie | D5: Date | E5: Désignation
B6: 60800000 | D6: 43946 | E6: Caisse fin S02 | G6: Bénéfice S03 : | H6: =10675000 -> 10675000
B7: 16650000 | D7: 43947 | E7: Prix C2 Type 2
B8: 12000000 | D8: 43948 | E8: Prix Many
B9: 13225000 | D9: 43948 | E9: Prix G5 /12 125
C10: 50000 | D10: 43948 | E10: fasika et gravillon (Michel)
C11: 36000000 | D11: 43948 | E11: achat motos Rajou
C12: 100000 | D12: 43948 | E12: Essence mecanicien
C13: 400000 | D13: 43948 | E13: Mécanicien (04 GP)
B14: 24000000 | D14: 43949 | E14: Prix G5 Megafi gris
B15: 10500000 | D15: 43949 | E15: Prix Kymco Gp n°21
B16: 10250000 | D16: 43949 | E16: Prix Kymco Gp n°24
B17: 17250000 | D17: 43949 | E17: Prix RACING 150 Fi N°20
C18: 43200000 | D18: 43950 | E18: achat motos Rajou
C19: 50000 | D19: 43950 | E19: Essence
C20: 200000 | D20: 43951 | E20: Kevin (diluant, degripant, fil,essence…)
C21: 200000 | D21: 43951 | E21: Huile 15-40 *2 (kevin)
C22: 1175000 | D22: 43951 | E22: Achats (bobine, clé,…)
C23: 350000 | D23: 43952 | E23: Bendix, soudure, chaines,…
C24: 100000 | D24: 43952 | E24: Clés GP
C25: 350000 | D25: 43952 | E25: Mecanicien
C26: 25000 | D26: 43952 | E26: Petrole
C27: 2000000 | D27: 43953 | E27: Avance achat motos
A32: TOTAL | B32: =SUM(B6:B9,B14:B17) -> 164675000 | C32: =SUM(C10:C13,C18:C27) -> 84200000 | D32: RESTE: | E32: =B32-C32 -> 80475000 | F32: =E32-H6 -> 69800000 | G32: <= RESTE - Benefice

Sheet Flux E-S S02
C2: Flux Entrée et Sortie CAISSE MASTER SCOOT
A3: PRIX "FMG"
B5: Entrée | C5: Sortie | D5: Date | E5: 37400000 | F5: Caisse 22/04/2020
B6: 16500000 | D6: 43941 | E6: 94800000 | F6: Caisse 22/04/2020
B7: 16400000 | D7: 43941 | E7: 57875000 | F7: Caisse 24/04/2020
B8: 16000000 | D8: 43941 | E8: =F35 -> 60375000 | F8: Caisse 25/04/2020
B9: 17250000 | D9: 43942
B10: 15000000 | D10: 43942
B11: 15500000 | D11: 43942
C12: 67250000 | D12: 43942
C13: 50000 | D13: 43942
B14: 14400000 | D14: 43943
C15: 10000000 | D15: 43943
B16: 14600000 | D16: =D15 -> 43943
C17: 50000 | D17: =D16 -> 43943
B18: 22500000 | D18: 43944
B19: 14000000 | D19: 43944
B20: 11000000 | D20: 43944
B21: 13425000 | D21: 43944
C22: 21600000 | D22: 43945
C23: 15000000 | D23: 43945
C24: 125000 | D24: 43945
C25: 75000 | D25: 43945
C26: 125000 | D26: 43945
C27: 425000 | D27: 43946
C28: 325000 | D28: 43946
A35: TOTAL | B35: =B11+B10+B9+B8+B7+B6+B14+B16+B18+B19+B20+B21+B29+B30 -> 186575000 | C35: =C17+C15+C13+C12+C22+C23+C24+C25+C26+C27+C28 -> 115025000 | D35: RESTE: | E35: =B35-C35 -> 71550000 | F35: =E35-11175000 -> 60375000 | G35: <= RESTE - Benefice
